[2023-09-22T17:21:30.410+0700] {taskinstance.py:1157} INFO - Dependencies all met for dep_context=non-requeueable deps ti=<TaskInstance: crawl_dag_v01.run_my_async_task manual__2023-09-22T09:05:17.387394+00:00 [queued]>
[2023-09-22T17:21:30.417+0700] {taskinstance.py:1157} INFO - Dependencies all met for dep_context=requeueable deps ti=<TaskInstance: crawl_dag_v01.run_my_async_task manual__2023-09-22T09:05:17.387394+00:00 [queued]>
[2023-09-22T17:21:30.417+0700] {taskinstance.py:1359} INFO - Starting attempt 4 of 9
[2023-09-22T17:21:30.426+0700] {taskinstance.py:1380} INFO - Executing <Task(PythonOperator): run_my_async_task> on 2023-09-22 09:05:17.387394+00:00
[2023-09-22T17:21:30.430+0700] {standard_task_runner.py:57} INFO - Started process 1780 to run task
[2023-09-22T17:21:30.434+0700] {standard_task_runner.py:84} INFO - Running: ['***', 'tasks', 'run', 'crawl_dag_v01', 'run_my_async_task', 'manual__2023-09-22T09:05:17.387394+00:00', '--job-id', '66', '--raw', '--subdir', 'DAGS_FOLDER/crawlInvest.py', '--cfg-path', '/tmp/tmp1dsm7__j']
[2023-09-22T17:21:30.436+0700] {standard_task_runner.py:85} INFO - Job 66: Subtask run_my_async_task
[2023-09-22T17:21:30.480+0700] {task_command.py:415} INFO - Running <TaskInstance: crawl_dag_v01.run_my_async_task manual__2023-09-22T09:05:17.387394+00:00 [running]> on host 92f43f7b42a7
[2023-09-22T17:21:30.544+0700] {taskinstance.py:1660} INFO - Exporting env vars: AIRFLOW_CTX_DAG_OWNER='linhhv' AIRFLOW_CTX_DAG_ID='crawl_dag_v01' AIRFLOW_CTX_TASK_ID='run_my_async_task' AIRFLOW_CTX_EXECUTION_DATE='2023-09-22T09:05:17.387394+00:00' AIRFLOW_CTX_TRY_NUMBER='4' AIRFLOW_CTX_DAG_RUN_ID='manual__2023-09-22T09:05:17.387394+00:00'
[2023-09-22T17:21:30.557+0700] {taskinstance.py:1935} ERROR - Task failed with exception
Traceback (most recent call last):
  File "/home/airflow/.local/lib/python3.8/site-packages/airflow/operators/python.py", line 192, in execute
    return_value = self.execute_callable()
  File "/home/airflow/.local/lib/python3.8/site-packages/airflow/operators/python.py", line 209, in execute_callable
    return self.python_callable(*self.op_args, **self.op_kwargs)
  File "/opt/airflow/dags/crawlInvest.py", line 143, in run_my_async_task
    asyncio.run(crawl(Code_stock))
  File "/usr/local/lib/python3.8/asyncio/runners.py", line 44, in run
    return loop.run_until_complete(main)
  File "/usr/local/lib/python3.8/asyncio/base_events.py", line 616, in run_until_complete
    return future.result()
  File "/opt/airflow/dags/crawlInvest.py", line 85, in crawl
    timestamp = datetime.datetime.now().strftime('%Y_%m_%d_%H_%M_%S')
AttributeError: type object 'datetime.datetime' has no attribute 'datetime'
[2023-09-22T17:21:30.570+0700] {taskinstance.py:1398} INFO - Marking task as UP_FOR_RETRY. dag_id=crawl_dag_v01, task_id=run_my_async_task, execution_date=20230922T090517, start_date=20230922T102130, end_date=20230922T102130
[2023-09-22T17:21:30.578+0700] {standard_task_runner.py:104} ERROR - Failed to execute job 66 for task run_my_async_task (type object 'datetime.datetime' has no attribute 'datetime'; 1780)
[2023-09-22T17:21:30.606+0700] {local_task_job_runner.py:228} INFO - Task exited with return code 1
[2023-09-22T17:21:30.626+0700] {taskinstance.py:2776} INFO - 0 downstream tasks scheduled from follow-on schedule check
