[2023-09-22T17:21:03.650+0700] {taskinstance.py:1157} INFO - Dependencies all met for dep_context=non-requeueable deps ti=<TaskInstance: crawl_dag_v01.run_my_async_task manual__2023-09-22T09:05:17.387394+00:00 [queued]>
[2023-09-22T17:21:03.656+0700] {taskinstance.py:1157} INFO - Dependencies all met for dep_context=requeueable deps ti=<TaskInstance: crawl_dag_v01.run_my_async_task manual__2023-09-22T09:05:17.387394+00:00 [queued]>
[2023-09-22T17:21:03.657+0700] {taskinstance.py:1359} INFO - Starting attempt 3 of 8
[2023-09-22T17:21:03.666+0700] {taskinstance.py:1380} INFO - Executing <Task(PythonOperator): run_my_async_task> on 2023-09-22 09:05:17.387394+00:00
[2023-09-22T17:21:03.670+0700] {standard_task_runner.py:57} INFO - Started process 1769 to run task
[2023-09-22T17:21:03.674+0700] {standard_task_runner.py:84} INFO - Running: ['***', 'tasks', 'run', 'crawl_dag_v01', 'run_my_async_task', 'manual__2023-09-22T09:05:17.387394+00:00', '--job-id', '65', '--raw', '--subdir', 'DAGS_FOLDER/crawlInvest.py', '--cfg-path', '/tmp/tmpyowz19t4']
[2023-09-22T17:21:03.675+0700] {standard_task_runner.py:85} INFO - Job 65: Subtask run_my_async_task
[2023-09-22T17:21:03.721+0700] {task_command.py:415} INFO - Running <TaskInstance: crawl_dag_v01.run_my_async_task manual__2023-09-22T09:05:17.387394+00:00 [running]> on host 92f43f7b42a7
[2023-09-22T17:21:03.782+0700] {taskinstance.py:1660} INFO - Exporting env vars: AIRFLOW_CTX_DAG_OWNER='linhhv' AIRFLOW_CTX_DAG_ID='crawl_dag_v01' AIRFLOW_CTX_TASK_ID='run_my_async_task' AIRFLOW_CTX_EXECUTION_DATE='2023-09-22T09:05:17.387394+00:00' AIRFLOW_CTX_TRY_NUMBER='3' AIRFLOW_CTX_DAG_RUN_ID='manual__2023-09-22T09:05:17.387394+00:00'
[2023-09-22T17:21:03.795+0700] {taskinstance.py:1935} ERROR - Task failed with exception
Traceback (most recent call last):
  File "/home/airflow/.local/lib/python3.8/site-packages/airflow/operators/python.py", line 192, in execute
    return_value = self.execute_callable()
  File "/home/airflow/.local/lib/python3.8/site-packages/airflow/operators/python.py", line 209, in execute_callable
    return self.python_callable(*self.op_args, **self.op_kwargs)
  File "/opt/airflow/dags/crawlInvest.py", line 143, in run_my_async_task
    asyncio.run(crawl(Code_stock))
  File "/usr/local/lib/python3.8/asyncio/runners.py", line 44, in run
    return loop.run_until_complete(main)
  File "/usr/local/lib/python3.8/asyncio/base_events.py", line 616, in run_until_complete
    return future.result()
  File "/opt/airflow/dags/crawlInvest.py", line 85, in crawl
    timestamp = dt.datetime.now().strftime('%Y_%m_%d_%H_%M_%S')
NameError: name 'dt' is not defined
[2023-09-22T17:21:03.809+0700] {taskinstance.py:1398} INFO - Marking task as UP_FOR_RETRY. dag_id=crawl_dag_v01, task_id=run_my_async_task, execution_date=20230922T090517, start_date=20230922T102103, end_date=20230922T102103
[2023-09-22T17:21:03.816+0700] {standard_task_runner.py:104} ERROR - Failed to execute job 65 for task run_my_async_task (name 'dt' is not defined; 1769)
[2023-09-22T17:21:03.847+0700] {local_task_job_runner.py:228} INFO - Task exited with return code 1
[2023-09-22T17:21:03.864+0700] {taskinstance.py:2776} INFO - 0 downstream tasks scheduled from follow-on schedule check
