[2023-09-28T14:18:44.366+0700] {taskinstance.py:1157} INFO - Dependencies all met for dep_context=non-requeueable deps ti=<TaskInstance: crawl_dag_v01.run_my_async_task scheduled__2023-09-22T02:00:00+00:00 [queued]>
[2023-09-28T14:18:44.381+0700] {taskinstance.py:1157} INFO - Dependencies all met for dep_context=requeueable deps ti=<TaskInstance: crawl_dag_v01.run_my_async_task scheduled__2023-09-22T02:00:00+00:00 [queued]>
[2023-09-28T14:18:44.382+0700] {taskinstance.py:1359} INFO - Starting attempt 1 of 6
[2023-09-28T14:18:44.398+0700] {taskinstance.py:1380} INFO - Executing <Task(PythonOperator): run_my_async_task> on 2023-09-22 02:00:00+00:00
[2023-09-28T14:18:44.405+0700] {standard_task_runner.py:57} INFO - Started process 1240 to run task
[2023-09-28T14:18:44.413+0700] {standard_task_runner.py:84} INFO - Running: ['***', 'tasks', 'run', 'crawl_dag_v01', 'run_my_async_task', 'scheduled__2023-09-22T02:00:00+00:00', '--job-id', '148', '--raw', '--subdir', 'DAGS_FOLDER/crawlInvest.py', '--cfg-path', '/tmp/tmpa2dha6oy']
[2023-09-28T14:18:44.415+0700] {standard_task_runner.py:85} INFO - Job 148: Subtask run_my_async_task
[2023-09-28T14:18:44.490+0700] {task_command.py:415} INFO - Running <TaskInstance: crawl_dag_v01.run_my_async_task scheduled__2023-09-22T02:00:00+00:00 [running]> on host 052a1d3faae2
[2023-09-28T14:18:44.607+0700] {taskinstance.py:1660} INFO - Exporting env vars: AIRFLOW_CTX_DAG_OWNER='linhhv' AIRFLOW_CTX_DAG_ID='crawl_dag_v01' AIRFLOW_CTX_TASK_ID='run_my_async_task' AIRFLOW_CTX_EXECUTION_DATE='2023-09-22T02:00:00+00:00' AIRFLOW_CTX_TRY_NUMBER='1' AIRFLOW_CTX_DAG_RUN_ID='scheduled__2023-09-22T02:00:00+00:00'
[2023-09-28T14:18:44.641+0700] {logging_mixin.py:151} INFO - ['ASG', 'BAX', 'BCF', 'BSA', 'BSH', 'DHB', 'DP2', 'DSG', 'DTK', 'EIC']
[2023-09-28T14:18:44.643+0700] {logging_mixin.py:151} INFO - etl_ingest_time_2023_09_28_14_18_44
[2023-09-28T14:18:45.171+0700] {taskinstance.py:1935} ERROR - Task failed with exception
Traceback (most recent call last):
  File "/home/airflow/.local/lib/python3.8/site-packages/airflow/operators/python.py", line 192, in execute
    return_value = self.execute_callable()
  File "/home/airflow/.local/lib/python3.8/site-packages/airflow/operators/python.py", line 209, in execute_callable
    return self.python_callable(*self.op_args, **self.op_kwargs)
  File "/opt/airflow/dags/crawlInvest.py", line 161, in run_my_async_task
    asyncio.run(crawl(Code_stock))
  File "/usr/local/lib/python3.8/asyncio/runners.py", line 44, in run
    return loop.run_until_complete(main)
  File "/usr/local/lib/python3.8/asyncio/base_events.py", line 616, in run_until_complete
    return future.result()
  File "/opt/airflow/dags/crawlInvest.py", line 97, in crawl
    cursor.execute(query_db)
pyodbc.ProgrammingError: ('42000', "[42000] [Microsoft][ODBC Driver 18 for SQL Server][SQL Server]Database 'etl_ingest_time_2023_09_28_14_18_44' already exists. Choose a different database name. (1801) (SQLExecDirectW)")
[2023-09-28T14:18:45.201+0700] {taskinstance.py:1398} INFO - Marking task as UP_FOR_RETRY. dag_id=crawl_dag_v01, task_id=run_my_async_task, execution_date=20230922T020000, start_date=20230928T071844, end_date=20230928T071845
[2023-09-28T14:18:45.223+0700] {standard_task_runner.py:104} ERROR - Failed to execute job 148 for task run_my_async_task (('42000', "[42000] [Microsoft][ODBC Driver 18 for SQL Server][SQL Server]Database 'etl_ingest_time_2023_09_28_14_18_44' already exists. Choose a different database name. (1801) (SQLExecDirectW)"); 1240)
[2023-09-28T14:18:45.271+0700] {local_task_job_runner.py:228} INFO - Task exited with return code 1
[2023-09-28T14:18:45.294+0700] {taskinstance.py:2776} INFO - 0 downstream tasks scheduled from follow-on schedule check
